Workbook

Sheet Concepts
A1: KitchenOS: engineering concepts checklist
A2: How to use: edit only the yellow columns (Status, Owner, Notes). Status uses the dropdown. Example: Status = In progress, Owner = Saty, Notes = unique index added on orders. Top-7 rank comes from the suggested priority order (1 = do first); blank = not in the top 7.
A4: Category | B4: Concept | C4: What it means | D4: Where you need it in KitchenOS | E4: Top-7 rank | F4: Status | G4: Owner | H4: Notes
A5: Correctness & Data Integrity | B5: Idempotency | C5: Repeating a request has the same effect as doing it once | D5: Webhooks, "Mark Ready", stock deduction | E5: 1 | F5: Not started
A6: Correctness & Data Integrity | B6: Unique constraints | C6: The database refuses duplicates | D6: One order per platform order ID, one ledger row per item and ingredient | E6: 1 | F6: Not started
A7: Correctness & Data Integrity | B7: ACID transactions | C7: A group of writes succeeds or fails together | D7: Order save + stock deduction | E7: 2 | F7: Not started
A8: Correctness & Data Integrity | B8: Optimistic locking | C8: A version number stops two people overwriting each other | D8: Menu edits, stock adjustments | F8: Not started
A9: Correctness & Data Integrity | B9: State machine | C9: Only valid status transitions allowed | D9: Order lifecycle | F9: Not started
A10: Correctness & Data Integrity | B10: Event sourcing / append-only ledger | C10: Store changes, not just current values | D10: Stock, payouts | E10: 2 | F10: Not started
A11: Correctness & Data Integrity | B11: Outbox / inbox pattern | C11: Reliable event publishing and consuming | D11: Order → inventory → margin updates | F11: Not started
A12: Correctness & Data Integrity | B12: Reconciliation | C12: Scheduled checks that two sources agree | D12: Ledger vs balance, our orders vs platform's | F12: Not started
A13: Correctness & Data Integrity | B13: Money handling | C13: Integer paise, rate snapshots, one rounding point | D13: Margin engine | F13: Not started
A14: Correctness & Data Integrity | B14: Data validation | C14: Reject bad input at the edge | D14: Aggregator payloads, manual entry | F14: Not started
A15: Performance | B15: Indexing | C15: Fast lookups for known queries | D15: Queue, KDS, history | E15: 4 | F15: Not started
A16: Performance | B16: Partial indexes | C16: Index only the rows you query | D16: Open orders only | E16: 4 | F16: Not started
A17: Performance | B17: Partitioning | C17: Split big tables by time or tenant | D17: Orders, ledger | E17: 4 | F17: Not started
A18: Performance | B18: Caching | C18: Keep hot data in memory | D18: Menus, recipes, settings | F18: Not started
A19: Performance | B19: Denormalized balances | C19: Store computed totals | D19: Stock balance per ingredient | F19: Not started
A20: Performance | B20: Read replicas / CQRS | C20: Separate heavy reads from writes | D20: Reports and dashboards | F20: Not started
A21: Performance | B21: Pagination / cursors | C21: Never load unbounded lists | D21: Order history, ledger | F21: Not started
A22: Performance | B22: Connection pooling | C22: Reuse database connections | D22: Every backend service | F22: Not started
A23: Performance | B23: Batching and debouncing | C23: Combine many small operations | D23: Platform menu sync | F23: Not started
A24: Reliability & Resilience | B24: Retries with backoff and jitter | C24: Retry smartly without causing storms | D24: Aggregator calls | E24: 5 | F24: Not started
A25: Reliability & Resilience | B25: Timeouts | C25: Never wait forever | D25: Every external call | F25: Not started
A26: Reliability & Resilience | B26: Circuit breaker | C26: Stop calling a failing service | D26: Swiggy or Zomato outage | E26: 5 | F26: Not started
A27: Reliability & Resilience | B27: Bulkheads | C27: Isolate failures to one part | D27: One adapter per platform | F27: Not started
A28: Reliability & Resilience | B28: Dead-letter queue | C28: Park failed messages for review | D28: Unprocessable orders | F28: Not started
A29: Reliability & Resilience | B29: Graceful degradation | C29: Core flow works when side features fail | D29: Orders work if reports are down | F29: Not started
A30: Reliability & Resilience | B30: Offline-first / local sync | C30: Work without internet, sync later | D30: Tablet KDS | E30: 5 | F30: Not started
A31: Reliability & Resilience | B31: Backpressure and queues | C31: Absorb spikes without dropping work | D31: Dinner rush | F31: Not started
A32: Reliability & Resilience | B32: Health checks and failover | C32: Detect and replace failed nodes | D32: Multi-AZ database and app | F32: Not started
A33: Reliability & Resilience | B33: Backups and restore drills | C33: Backups you've actually restored | D33: Point-in-time recovery | F33: Not started
A34: Scalability | B34: Statelessness | C34: Any server can handle any request | D34: App servers | F34: Not started
A35: Scalability | B35: Horizontal scaling | C35: Add machines, not bigger machines | D35: API and workers | F35: Not started
A36: Scalability | B36: Multi-tenancy | C36: Many customers on one system, safely | D36: tenant_id everywhere | E36: 3 | F36: Not started
A37: Scalability | B37: Sharding / cells | C37: Independent stacks per group of tenants | D37: Beyond tens of thousands of kitchens | F37: Not started
A38: Scalability | B38: Rate limiting / quotas | C38: One tenant can't starve the others | D38: API and webhooks | F38: Not started
A39: Scalability | B39: Event streaming | C39: Durable, replayable event log | D39: Analytics, integrations | F39: Not started
A40: Scalability | B40: Autoscaling | C40: Capacity follows load | D40: Evening peaks | F40: Not started
A41: Scalability | B41: Hot-key handling | C41: Spread load on shared rows | D41: Common ingredients | F41: Not started
...

Sheet Top 7 Priorities
A1: What matters most, in order
A3: Rank | B3: Focus area | C3: Concepts covered | D3: Concepts in group | E3: Done | F3: % done
A4: 1 | B4: Idempotency + unique constraints | C4: Idempotency; Unique constraints | D4: =COUNTIF(Concepts!$E$5:$E$68,A4) -> 2 | E4: =COUNTIFS(Concepts!$E$5:$E$68,A4,Concepts!$F$5:$F$68,"Done") -> 0 | F4: =IF(D4=0,0,E4/D4) -> 0
A5: 2 | B5: Append-only ledger + transactions | C5: ACID transactions; Event sourcing / append-only ledger | D5: =COUNTIF(Concepts!$E$5:$E$68,A5) -> 2 | E5: =COUNTIFS(Concepts!$E$5:$E$68,A5,Concepts!$F$5:$F$68,"Done") -> 0 | F5: =IF(D5=0,0,E5/D5) -> 0
A6: 3 | B6: Multi-tenancy + row-level security | C6: Multi-tenancy; Row-level security | D6: =COUNTIF(Concepts!$E$5:$E$68,A6) -> 2 | E6: =COUNTIFS(Concepts!$E$5:$E$68,A6,Concepts!$F$5:$F$68,"Done") -> 0 | F6: =IF(D6=0,0,E6/D6) -> 0
A7: 4 | B7: Indexing + partitioning | C7: Indexing; Partial indexes; Partitioning | D7: =COUNTIF(Concepts!$E$5:$E$68,A7) -> 3 | E7: =COUNTIFS(Concepts!$E$5:$E$68,A7,Concepts!$F$5:$F$68,"Done") -> 0 | F7: =IF(D7=0,0,E7/D7) -> 0
A8: 5 | B8: Offline-first + retries / circuit breakers | C8: Retries with backoff and jitter; Circuit breaker; Offline-first / local sync | D8: =COUNTIF(Concepts!$E$5:$E$68,A8) -> 3 | E8: =COUNTIFS(Concepts!$E$5:$E$68,A8,Concepts!$F$5:$F$68,"Done") -> 0 | F8: =IF(D8=0,0,E8/D8) -> 0
A9: 6 | B9: Observability + business-signal alerts | C9: Structured logging; Business-signal alerts | D9: =COUNTIF(Concepts!$E$5:$E$68,A9) -> 2 | E9: =COUNTIFS(Concepts!$E$5:$E$68,A9,Concepts!$F$5:$F$68,"Done") -> 0 | F9: =IF(D9=0,0,E9/D9) -> 0
A10: 7 | B10: Testing for concurrency and money | C10: Concurrency tests; Property-based tests | D10: =COUNTIF(Concepts!$E$5:$E$68,A10) -> 2 | E10: =COUNTIFS(Concepts!$E$5:$E$68,A10,Concepts!$F$5:$F$68,"Done") -> 0 | F10: =IF(D10=0,0,E10/D10) -> 0
A12: Counts and % done update automatically from the Status column on the Concepts sheet.

Sheet Summary
A1: Progress by category
A3: Category | B3: Total | C3: Not started | D3: In progress | E3: Done | F3: Not needed | G3: % done (excl. not needed)
A4: Correctness & Data Integrity | B4: =COUNTIF(Concepts!$A$5:$A$68,A4) -> 10 | C4: =COUNTIFS(Concepts!$A$5:$A$68,$A4,Concepts!$F$5:$F$68,"Not started") -> 10 | D4: =COUNTIFS(Concepts!$A$5:$A$68,$A4,Concepts!$F$5:$F$68,"In progress") -> 0 | E4: =COUNTIFS(Concepts!$A$5:$A$68,$A4,Concepts!$F$5:$F$68,"Done") -> 0 | F4: =COUNTIFS(Concepts!$A$5:$A$68,$A4,Concepts!$F$5:$F$68,"Not needed") -> 0 | G4: =IF(B4-F4=0,0,E4/(B4-F4)) -> 0
A5: Performance | B5: =COUNTIF(Concepts!$A$5:$A$68,A5) -> 9 | C5: =COUNTIFS(Concepts!$A$5:$A$68,$A5,Concepts!$F$5:$F$68,"Not started") -> 9 | D5: =COUNTIFS(Concepts!$A$5:$A$68,$A5,Concepts!$F$5:$F$68,"In progress") -> 0 | E5: =COUNTIFS(Concepts!$A$5:$A$68,$A5,Concepts!$F$5:$F$68,"Done") -> 0 | F5: =COUNTIFS(Concepts!$A$5:$A$68,$A5,Concepts!$F$5:$F$68,"Not needed") -> 0 | G5: =IF(B5-F5=0,0,E5/(B5-F5)) -> 0
A6: Reliability & Resilience | B6: =COUNTIF(Concepts!$A$5:$A$68,A6) -> 10 | C6: =COUNTIFS(Concepts!$A$5:$A$68,$A6,Concepts!$F$5:$F$68,"Not started") -> 10 | D6: =COUNTIFS(Concepts!$A$5:$A$68,$A6,Concepts!$F$5:$F$68,"In progress") -> 0 | E6: =COUNTIFS(Concepts!$A$5:$A$68,$A6,Concepts!$F$5:$F$68,"Done") -> 0 | F6: =COUNTIFS(Concepts!$A$5:$A$68,$A6,Concepts!$F$5:$F$68,"Not needed") -> 0 | G6: =IF(B6-F6=0,0,E6/(B6-F6)) -> 0
A7: Scalability | B7: =COUNTIF(Concepts!$A$5:$A$68,A7) -> 8 | C7: =COUNTIFS(Concepts!$A$5:$A$68,$A7,Concepts!$F$5:$F$68,"Not started") -> 8 | D7: =COUNTIFS(Concepts!$A$5:$A$68,$A7,Concepts!$F$5:$F$68,"In progress") -> 0 | E7: =COUNTIFS(Concepts!$A$5:$A$68,$A7,Concepts!$F$5:$F$68,"Done") -> 0 | F7: =COUNTIFS(Concepts!$A$5:$A$68,$A7,Concepts!$F$5:$F$68,"Not needed") -> 0 | G7: =IF(B7-F7=0,0,E7/(B7-F7)) -> 0
A8: Security | B8: =COUNTIF(Concepts!$A$5:$A$68,A8) -> 8 | C8: =COUNTIFS(Concepts!$A$5:$A$68,$A8,Concepts!$F$5:$F$68,"Not started") -> 8 | D8: =COUNTIFS(Concepts!$A$5:$A$68,$A8,Concepts!$F$5:$F$68,"In progress") -> 0 | E8: =COUNTIFS(Concepts!$A$5:$A$68,$A8,Concepts!$F$5:$F$68,"Done") -> 0 | F8: =COUNTIFS(Concepts!$A$5:$A$68,$A8,Concepts!$F$5:$F$68,"Not needed") -> 0 | G8: =IF(B8-F8=0,0,E8/(B8-F8)) -> 0
A9: Observability & Operations | B9: =COUNTIF(Concepts!$A$5:$A$68,A9) -> 9 | C9: =COUNTIFS(Concepts!$A$5:$A$68,$A9,Concepts!$F$5:$F$68,"Not started") -> 9 | D9: =COUNTIFS(Concepts!$A$5:$A$68,$A9,Concepts!$F$5:$F$68,"In progress") -> 0 | E9: =COUNTIFS(Concepts!$A$5:$A$68,$A9,Concepts!$F$5:$F$68,"Done") -> 0 | F9: =COUNTIFS(Concepts!$A$5:$A$68,$A9,Concepts!$F$5:$F$68,"Not needed") -> 0 | G9: =IF(B9-F9=0,0,E9/(B9-F9)) -> 0
A10: Testing | B10: =COUNTIF(Concepts!$A$5:$A$68,A10) -> 5 | C10: =COUNTIFS(Concepts!$A$5:$A$68,$A10,Concepts!$F$5:$F$68,"Not started") -> 5 | D10: =COUNTIFS(Concepts!$A$5:$A$68,$A10,Concepts!$F$5:$F$68,"In progress") -> 0 | E10: =COUNTIFS(Concepts!$A$5:$A$68,$A10,Concepts!$F$5:$F$68,"Done") -> 0 | F10: =COUNTIFS(Concepts!$A$5:$A$68,$A10,Concepts!$F$5:$F$68,"Not needed") -> 0 | G10: =IF(B10-F10=0,0,E10/(B10-F10)) -> 0
A11: Product-Level | B11: =COUNTIF(Concepts!$A$5:$A$68,A11) -> 5 | C11: =COUNTIFS(Concepts!$A$5:$A$68,$A11,Concepts!$F$5:$F$68,"Not started") -> 5 | D11: =COUNTIFS(Concepts!$A$5:$A$68,$A11,Concepts!$F$5:$F$68,"In progress") -> 0 | E11: =COUNTIFS(Concepts!$A$5:$A$68,$A11,Concepts!$F$5:$F$68,"Done") -> 0 | F11: =COUNTIFS(Concepts!$A$5:$A$68,$A11,Concepts!$F$5:$F$68,"Not needed") -> 0 | G11: =IF(B11-F11=0,0,E11/(B11-F11)) -> 0
A12: Total | B12: =SUM(B4:B11) -> 64 | C12: =SUM(C4:C11) -> 64 | D12: =SUM(D4:D11) -> 0 | E12: =SUM(E4:E11) -> 0 | F12: =SUM(F4:F11) -> 0 | G12: =IF(B12-F12=0,0,E12/(B12-F12)) -> 0
